Workbook

Sheet الربع الأول 2024
A2: 1 | D2: تقييم خطتك | F2: =(F23+F53+F83+F113+F143+F173+F203+F233+F263+F293+F323+F353+F383+F397+F427+F457)/14 -> 0.7 | H2: تقييم ادائك حتى اليوم | J2: =(J23+J53+J83+J113+J143+J173+J203+J233+J263+J293+J323+J353+J383+J397)/14 -> 0.671875
A3: التقويم الأسبوعي | B3: الخطة والتقرير الأسبوعي
B4: خطة الأسبوع من / / 2024
B5: اليوم | C5: المهنة | D5: درجة الأهمية | E5: عاجلة | F5: تقييم أهمية المهمة من11 | G5: اليوم | H5: المهمة | I5: الإنجاز | J5: تقييم درجة الإنجاز من 10 | K5: السبب
A6: 45292 | B6: الاثنين | D6: درجة الأهمية | F6: 7 | G6: الاثنين | I6: تم | J6: 7
D7: درجة الأهمية | F7: 7 | I7: تم | J7: 7
D8: درجة الأهمية | F8: 7 | I8: تم | J8: 7
D9: درجة الأهمية | F9: 7 | I9: تم | J9: 7
A10: 45293 | B10: الثلاثاء | D10: درجة الأهمية | F10: 7 | G10: الثلاثاء | I10: تم | J10: 7
D11: درجة الأهمية | F11: 7 | I11: تم | J11: 7
D12: درجة الأهمية | F12: 7 | I12: تم | J12: 7
D13: درجة الأهمية | F13: 7 | I13: تم | J13: 7
A14: 45294 | B14: الأربعاء | D14: درجة الأهمية | F14: 7 | G14: الأربعاء | I14: تم | J14: 7
D15: درجة الأهمية | F15: 7 | I15: تم | J15: 7
D16: درجة الأهمية | F16: 7 | I16: تم | J16: 7
D17: درجة الأهمية | F17: 7 | I17: تم | J17: 7
A18: 45295 | B18: الخميس | D18: درجة الأهمية | F18: 7 | G18: الخميس | I18: تم | J18: 0
D19: درجة الأهمية | F19: 7 | I19: تم | J19: 7
D20: درجة الأهمية | F20: 7 | I20: تم | J20: 7
D21: درجة الأهمية | F21: 7 | I21: تم | J21: 7
D22: مجموع النقاط من 160 | F22: =SUM(F6:F21) -> 112 | H22: مجموع النقاط من 160 | J22: =SUM(J6:J21) -> 105
D23: تقييم الخطة | F23: =F22/160*1 -> 0.7 | H23: تقييم الأداء للأسبوع | J23: =J22/160*1 -> 0.65625
A24: 2
A25: التقويم الأسبوعي | B25: الخطة والتقرير الأسبوعي
B26: خطة الأسبوع من / / 2024 | G26: تقرير الأسبوع الحالي من / /2024
B27: اليوم | C27: المهنة | D27: درجة الأهمية | E27: عاجلة | F27: تقييم أهمية المهمة من11 | G27: اليوم | H27: المهمة | I27: الإنجاز | J27: تقييم درجة الإنجاز من 10 | K27: السبب
A28: 45297 | B28: السبت | D28: درجة الأهمية | F28: 7 | G28: السبت | I28: تم | J28: 7
D29: درجة الأهمية | F29: 7 | I29: تم | J29: 7
D30: درجة الأهمية | F30: 7 | I30: تم | J30: 7
D31: درجة الأهمية | F31: 7 | I31: تم | J31: 7
A32: 45298 | B32: الاحد | D32: درجة الأهمية | F32: 7 | G32: الاحد | I32: تم | J32: 7
D33: درجة الأهمية | F33: 7 | I33: تم | J33: 7
D34: درجة الأهمية | F34: 7 | I34: تم | J34: 7
D35: درجة الأهمية | F35: 7 | I35: تم | J35: 7
A36: 45299 | B36: الاثنين | D36: درجة الأهمية | F36: 7 | G36: الاثنين | I36: تم | J36: 7
D37: درجة الأهمية | F37: 7 | I37: تم | J37: 7
D38: درجة الأهمية | F38: 7 | I38: تم | J38: 7
D39: درجة الأهمية | F39: 7 | I39: تم | J39: 7
A40: 45300 | B40: الثلاثاء | D40: درجة الأهمية | F40: 7 | G40: الثلاثاء | I40: تم | J40: 7
D41: درجة الأهمية | F41: 7 | I41: تم | J41: 7
...

Sheet الربع الثاني 2024
A1: 1 | D1: تقييم خطتك | F1: =(F22+F52+F82+F112+F142+F172+F202+F232+F262+F292+F322+F352+F382+F400+F430+F460)/14 -> 0.7952381 | H1: تقييم ادائك حتى اليوم | J1: =(J22+J52+J82+J112+J142+J172+J202+J232+J262+J292+J322+J352+J382+J400)/14 -> 0.77857143
A2: التقويم الأسبوعي | B2: الخطة والتقرير الأسبوعي
B3: خطة الأسبوع من / / 2024 | G3: تقرير الأسبوع الحالي من / /2024
B4: اليوم | C4: المهنة | D4: درجة الأهمية | E4: عاجلة | F4: تقييم أهمية المهمة من11 | G4: اليوم | H4: التقرير | I4: الإنجاز | J4: تقييم درجة الإنجاز من 10 | K4: الملاحظات
A5: 45383 | B5: الاثنين | D5: درجة الأهمية | F5: 10 | G5: الاثنين | I5: تم | J5: 10
D6: درجة الأهمية | F6: 10 | I6: تم | J6: 10
D7: درجة الأهمية | F7: 10 | I7: تم | J7: 10
D8: درجة الأهمية | F8: 10 | I8: تم | J8: 10
A9: 45384 | B9: الثلاثاء | D9: درجة الأهمية | F9: 10 | G9: الثلاثاء | I9: تم | J9: 10
D10: درجة الأهمية | F10: 10 | I10: تم | J10: 10
D11: درجة الأهمية | F11: 10 | I11: تم | J11: 10
D12: درجة الأهمية | F12: 10 | I12: تم | J12: 10
A13: 45385 | B13: الأربعاء | D13: درجة الأهمية | F13: 10 | G13: الأربعاء | I13: تم | J13: 10
D14: درجة الأهمية | F14: 10 | I14: تم | J14: 10
D15: درجة الأهمية | F15: 10 | I15: تم | J15: 10
D16: درجة الأهمية | F16: 10 | I16: تم | J16: 10
A17: 45386 | B17: الخميس | D17: درجة الأهمية | F17: 10 | G17: الخميس | I17: تم | J17: 10
D18: درجة الأهمية | F18: 10 | I18: تم | J18: 10
D19: درجة الأهمية | F19: 10 | I19: تم | J19: 10
D20: درجة الأهمية | F20: 10 | I20: تم | J20: 10
D21: مجموع النقاط من 160 | F21: =SUM(F5:F20) -> 160 | H21: مجموع النقاط من 160 | J21: =SUM(J5:J20) -> 160
D22: تقييم الخطة | F22: =F21/160*1 -> 1 | H22: تقييم الأداء للأسبوع | J22: =J21/160*1 -> 1
A23: 2
A24: التقويم الأسبوعي | B24: الخطة والتقرير الأسبوعي
B25: خطة الأسبوع من / / 2024 | G25: تقرير الأسبوع الحالي من / /2024
B26: اليوم | C26: المهنة | D26: درجة الأهمية | E26: عاجلة | F26: تقييم أهمية المهمة من11 | G26: اليوم | H26: المهمة | I26: الإنجاز | J26: تقييم درجة الإنجاز من 10 | K26: السبب
A27: 45388 | B27: السبت | D27: درجة الأهمية | F27: 10 | G27: السبت | I27: تم | J27: 10
D28: درجة الأهمية | F28: 10 | I28: تم | J28: 10
D29: درجة الأهمية | F29: 10 | I29: تم | J29: 10
D30: درجة الأهمية | F30: 10 | I30: تم | J30: 10
A31: 45389 | B31: الاحد | D31: درجة الأهمية | F31: 10 | G31: الاحد | I31: تم | J31: 10
D32: درجة الأهمية | F32: 10 | I32: تم | J32: 10
D33: درجة الأهمية | F33: 10 | I33: تم | J33: 10
D34: درجة الأهمية | F34: 10 | I34: تم | J34: 10
A35: 45390 | B35: الاثنين | D35: درجة الأهمية | F35: 10 | G35: الاثنين | I35: تم | J35: 10
D36: درجة الأهمية | F36: 10 | I36: تم | J36: 10
D37: درجة الأهمية | F37: 10 | I37: تم | J37: 10
D38: درجة الأهمية | F38: 10 | I38: تم | J38: 10
A39: 45391 | B39: الثلاثاء | D39: درجة الأهمية | F39: 10 | G39: الثلاثاء | I39: تم | J39: 10
D40: درجة الأهمية | F40: 10 | I40: تم | J40: 10
...

Sheet الربع الثالث 2024
A1: 1 | D1: تقييم خطتك | F1: =(F22+F52+F82+F112+F142+F172+F202+F232+F262+F292+F322+F352+F382+F400+F430+F460)/14 -> 0.69791667 | H1: تقييم ادائك حتى اليوم | J1: =(J22+J52+J82+J112+J142+J172+J202+J232+J262+J292+J322+J352+J382+J400)/14 -> 0.671875
A2: التقويم الأسبوعي | B2: الخطة والتقرير الأسبوعي
B3: خطة الأسبوع من / / 2024 | G3: تقرير الأسبوع الحالي من / /2024
B4: اليوم | C4: المهنة | D4: درجة الأهمية | E4: عاجلة | F4: تقييم أهمية المهمة من11 | G4: اليوم | H4: المهمة | I4: الإنجاز | J4: تقييم درجة الإنجاز من 10 | K4: السبب
A5: 45474 | B5: الاثنين | D5: درجة الأهمية | F5: 7 | G5: الاثنين | I5: تم | J5: 7
D6: درجة الأهمية | F6: 7 | I6: تم | J6: 7
D7: درجة الأهمية | F7: 7 | I7: تم | J7: 7
D8: درجة الأهمية | F8: 7 | I8: تم | J8: 7
A9: 45475 | B9: الثلاثاء | D9: درجة الأهمية | F9: 7 | G9: الثلاثاء | I9: تم | J9: 7
D10: درجة الأهمية | F10: 7 | I10: تم | J10: 7
D11: درجة الأهمية | F11: 7 | I11: تم | J11: 7
D12: درجة الأهمية | F12: 7 | I12: تم | J12: 7
A13: 45476 | B13: الأربعاء | D13: درجة الأهمية | F13: 7 | G13: الأربعاء | I13: تم | J13: 7
D14: درجة الأهمية | F14: 7 | I14: تم | J14: 7
D15: درجة الأهمية | F15: 7 | I15: تم | J15: 7
D16: درجة الأهمية | F16: 7 | I16: تم | J16: 7
A17: 45477 | B17: الخميس | D17: درجة الأهمية | F17: 7 | G17: الخميس | I17: تم | J17: 0
D18: درجة الأهمية | F18: 7 | I18: تم | J18: 7
D19: درجة الأهمية | F19: 7 | I19: تم | J19: 7
D20: درجة الأهمية | F20: 7 | I20: تم | J20: 7
D21: مجموع النقاط من 160 | F21: =SUM(F5:F20) -> 112 | H21: مجموع النقاط من 160 | J21: =SUM(J5:J20) -> 105
D22: تقييم الخطة | F22: =F21/160*1 -> 0.7 | H22: تقييم الأداء للأسبوع | J22: =J21/160*1 -> 0.65625
A23: 2
A24: التقويم الأسبوعي | B24: الخطة والتقرير الأسبوعي
B25: خطة الأسبوع من / / 2024 | G25: تقرير الأسبوع الحالي من / /2024
B26: اليوم | C26: المهنة | D26: درجة الأهمية | E26: عاجلة | F26: تقييم أهمية المهمة من11 | G26: اليوم | H26: المهمة | I26: الإنجاز | J26: تقييم درجة الإنجاز من 10 | K26: السبب
A27: 45479 | B27: السبت | D27: درجة الأهمية | G27: السبت | I27: تم | J27: 7
D28: درجة الأهمية | F28: 7 | I28: تم | J28: 7
D29: درجة الأهمية | F29: 7 | I29: تم | J29: 7
D30: درجة الأهمية | F30: 7 | I30: تم | J30: 7
A31: 45480 | B31: الاحد | D31: درجة الأهمية | F31: 7 | G31: الاحد | I31: تم | J31: 7
D32: درجة الأهمية | F32: 7 | I32: تم | J32: 7
D33: درجة الأهمية | F33: 7 | I33: تم | J33: 7
D34: درجة الأهمية | F34: 7 | I34: تم | J34: 7
A35: 45481 | B35: الاثنين | D35: درجة الأهمية | F35: 7 | G35: الاثنين | I35: تم | J35: 7
D36: درجة الأهمية | F36: 7 | I36: تم | J36: 7
D37: درجة الأهمية | F37: 7 | I37: تم | J37: 7
D38: درجة الأهمية | F38: 7 | I38: تم | J38: 7
A39: 45482 | B39: الثلاثاء | D39: درجة الأهمية | F39: 7 | G39: الثلاثاء | I39: تم | J39: 7
D40: درجة الأهمية | F40: 7 | I40: تم | J40: 7
...

Sheet الربع الرابع 2024
A2: 1 | D2: تقييم خطتك | F2: =(F19+F49+F79+F109+F139+F169+F199+F229+F259+F289+F319+F349+F379+F401+F431)/14 -> 0.7 | H2: تقييم ادائك حتى اليوم | J2: =(J19+J49+J79+J109+J139+J169+J199+J229+J259+J289+J319+J349+J379+J401)/14 -> 0.67708333
A3: التقويم الأسبوعي | B3: الخطة والتقرير الأسبوعي
B4: خطة الأسبوع من / / 2024 | G4: تقرير الأسبوع الحالي من / /2024
B5: اليوم | C5: المهنة | D5: درجة الأهمية | E5: عاجلة | F5: تقييم أهمية المهمة من11 | G5: اليوم | H5: المهمة | I5: الإنجاز | J5: تقييم درجة الإنجاز من 10 | K5: السبب
A6: 45566 | B6: الثلاثاء | D6: درجة الأهمية | F6: 7 | G6: الثلاثاء | I6: تم | J6: 7
D7: درجة الأهمية | F7: 7 | I7: تم | J7: 7
D8: درجة الأهمية | F8: 7 | I8: تم | J8: 7
D9: درجة الأهمية | F9: 7 | I9: تم | J9: 7
A10: 45567 | B10: الأربعاء | D10: درجة الأهمية | F10: 7 | G10: الأربعاء | I10: تم | J10: 7
D11: درجة الأهمية | F11: 7 | I11: تم | J11: 7
D12: درجة الأهمية | F12: 7 | I12: تم | J12: 7
D13: درجة الأهمية | F13: 7 | I13: تم | J13: 7
A14: 45568 | B14: الخميس | D14: درجة الأهمية | F14: 7 | G14: الخميس | I14: تم | J14: 7
D15: درجة الأهمية | F15: 7 | I15: تم | J15: 7
D16: درجة الأهمية | F16: 7 | I16: تم | J16: 7
D17: درجة الأهمية | F17: 7 | I17: تم | J17: 7
D18: مجموع النقاط من 120 | F18: =SUM(F6:F17) -> 84 | H18: مجموع النقاط من 120 | J18: =SUM(J6:J17) -> 84
D19: تقييم الخطة | F19: =F18/120*1 -> 0.7 | H19: تقييم الأداء للأسبوع | J19: =J18/120*1 -> 0.7
A20: 2
A21: التقويم الأسبوعي | B21: الخطة والتقرير الأسبوعي
B22: خطة الأسبوع من / / 2024 | G22: تقرير الأسبوع الحالي من / /2024
B23: اليوم | C23: المهنة | D23: درجة الأهمية | E23: عاجلة | F23: تقييم أهمية المهمة من11 | G23: اليوم | H23: المهمة | I23: الإنجاز | J23: تقييم درجة الإنجاز من 10 | K23: السبب
A24: 45570 | B24: السبت | D24: درجة الأهمية | F24: 7 | G24: السبت | I24: تم | J24: 7
D25: درجة الأهمية | F25: 7 | I25: تم | J25: 7
D26: درجة الأهمية | F26: 7 | I26: تم | J26: 7
D27: درجة الأهمية | F27: 7 | I27: تم | J27: 7
A28: 45571 | B28: الاحد | D28: درجة الأهمية | F28: 7 | G28: الاحد | I28: تم | J28: 7
D29: درجة الأهمية | F29: 7 | I29: تم | J29: 7
D30: درجة الأهمية | F30: 7 | I30: تم | J30: 7
D31: درجة الأهمية | F31: 7 | I31: تم | J31: 7
A32: 45572 | B32: الاثنين | D32: درجة الأهمية | F32: 7 | G32: الاثنين | I32: تم | J32: 7
D33: درجة الأهمية | F33: 7 | I33: تم | J33: 7
D34: درجة الأهمية | F34: 7 | I34: تم | J34: 7
D35: درجة الأهمية | F35: 7 | I35: تم | J35: 7
A36: 45573 | B36: الثلاثاء | D36: درجة الأهمية | F36: 7 | G36: الثلاثاء | I36: تم | J36: 7
D37: درجة الأهمية | F37: 7 | I37: تم | J37: 7
D38: درجة الأهمية | F38: 7 | I38: تم | J38: 7
D39: درجة الأهمية | F39: 7 | I39: تم | J39: 7
A40: 45574 | B40: الأربعاء | D40: درجة الأهمية | F40: 7 | G40: الأربعاء | I40: تم | J40: 7
D41: درجة الأهمية | F41: 7 | I41: تم | J41: 7
...

Sheet التقييم الشامل 
B3: التقييم الشامل للخطة والتقارير
B4: الربع | C4: الخطة | D4: التقرير
B5: الأول | C5: ='الربع الأول 2024'!F2 -> 0.7 | D5: ='الربع الأول 2024'!J2 -> 0.671875
B6: الثاني | C6: ='الربع الثاني 2024'!F1 -> 0.7952381 | D6: ='الربع الثاني 2024'!J1 -> 0.77857143
B7: الثالث | C7: ='الربع الثالث 2024'!F1 -> 0.69791667 | D7: ='الربع الثالث 2024'!J1 -> 0.671875
B8: الرابع | C8: ='الربع الرابع 2024'!F2 -> 0.7 | D8: ='الربع الرابع 2024'!J2 -> 0.67708333
B9: النهائي | C9: =SUM(C5:C8)/4 -> 0.72328869 | D9: =SUM(D5:D8)/4 -> 0.69985119
